Workbook
Name EM: Sheet2!$AA$2:$AA$33
Name Oranamate: Sheet2!$BD$3:$BD$34
Name TX_MDF: Sheet2!$Y$15:$Y$21
Name PLAIN_HDHMR: Sheet2!$B$211:$B$232
Name LAMINATED_HMR_PARTICLE: Sheet2!$B$194:$B$209
Name LAMINATED_HDHMR: Sheet2!$B$234:$B$280
Name AHPL: Sheet2!$AY$3:$AY$32
Name PLAIN_HMR_PARTICLE: Sheet2!$B$189:$B$192
Name PRODUCTS: Sheet2!$A$2:$A$20
Name ACRYLIC: Sheet2!$B$473
Name TYPE: Sheet2!$X$2:$X$11
Name PLAIN_BOILO: Sheet2!$B$429:$B$437
Name LAMINATED_BOILO: Sheet2!$B$439:$B$467
Name LM: Sheet2!$E$3:$E$175
Name Ornamate: Sheet2!$B$477
Name PLAIN_PARTICLE: Sheet2!$B$109:$B$127
Name LAMINATED_MDF: Sheet2!$B$41:$B$107
Name EDGE: Sheet2!$BI$3:$BI$34
Name PLAIN_HDHMR_DOOR: Sheet2!$B$282:$B$329
Name OM: Sheet2!$BD$3:$BD$34
Name TXD: Sheet2!$Z$7
Name LP: Sheet2!$I$3:$I$128
Name LMRD: Sheet2!$T$3:$T$128
Name FM_TX: Sheet2!$Z$8:$Z$11
Name PLAIN_MDF: Sheet2!$B$3:$B$39
Name EMBOSSED: Sheet2!$B$469
Name AH: Sheet2!$M$3:$M$13
Name EDGE_BAND: Sheet2!$BI$3:$BI$34
Name UV: Sheet2!$B$471
Name LAMINATED_HDHMR_DOOR: Sheet2!$B$331:$B$378
Name Z_CE96E5DA_0AC7_4DD6_B0FC_330A0E3CBA1D_.wvu.Cols: Sheet1!$K:$K
Name FM: Sheet2!$AP$3:$AP$6
Name LH: Sheet2!$T$3:$T$121
Name ACRYLIC_PLUS: Sheet2!$B$475
Name LAMINATED_PARTICLE: Sheet2!$B$129:$B$187
Name TX: Sheet2!$Z$2:$Z$3
Name HDHMR_METALLIC_DOOR: Sheet2!$B$380:$B$427
Name UM: Sheet2!$Q$3:$Q$185
Name LMR: Sheet2!$T$3:$T$175

Sheet Sheet1
A1: Customer Name (Billing Address, If Change) | E1: W.E.F | H1: Delivery Address (Mandatory)
E2: 45962
A4: Shri gulabrai sons | E4: PO Number (MANDATORY)
E7: Order Date
E8: 46162
A9: MO No :- | H9: ORDER WEIGHT(MT) | J9: =L33/1000 -> 0.04737 | L9: WRONG WEIGHT
A10: Contact Person :- | L10: OK WEIGHT
A11: S.NO | B11: PRODUCTS | C11: TYPE | D11: Thick.-SIZE | E11: Shade Code | F11: Shade Name+ | H11: Texture /FMS | I11: GRADE (A/B/C/CM) | J11: No. Of Boards | K11: WT | L11: Weight | M11: Remarks
A12: 1 | B12: LAMINATED_HDHMR | C12: =VLOOKUP(B12,Sheet2!W:X,2,FALSE) -> LMR | D12: 18.00-E-8x4--BSL | E12: 1108 | F12: =IFERROR(VLOOKUP(E12,Sheet2!AD:AE,2,0),"") -> Marigold Yellow | G12: =VLOOKUP(B12,Sheet2!B:D,3,FALSE) -> TX | H12: SD | I12: A | J12: 1 | K12: =IF(ISNA(VLOOKUP(D12,Sheet2!B:C,2,FALSE)),"0",(VLOOKUP(D12,Sheet2!B:C,2,FALSE))) -> 47.37 | L12: =J12*K12 -> 47.37 | P12: =VLOOKUP(C12,Sheet2!BM:BN,2,0) -> #N/A | Q12: =D12 -> 18.00-E-8x4--BSL
A13: 2 | C13: =VLOOKUP(B13,Sheet2!W:X,2,FALSE) -> #N/A | F13: =IFERROR(VLOOKUP(E13,Sheet2!AD:AE,2,0),"") | G13: =VLOOKUP(B13,Sheet2!B:D,3,FALSE) -> #N/A | I13: A | K13: =IF(ISNA(VLOOKUP(D13,Sheet2!B:C,2,FALSE)),"0",(VLOOKUP(D13,Sheet2!B:C,2,FALSE))) -> 0 | L13: =J13*K13 -> 0 | P13: =VLOOKUP(C13,Sheet2!BM:BN,2,0) -> #N/A | Q13: =D13
A14: 3 | C14: =VLOOKUP(B14,Sheet2!W:X,2,FALSE) -> #N/A | F14: =IFERROR(VLOOKUP(E14,Sheet2!AD:AE,2,0),"") | G14: =VLOOKUP(B14,Sheet2!B:D,3,FALSE) -> #N/A | I14: A | K14: =IF(ISNA(VLOOKUP(D14,Sheet2!B:C,2,FALSE)),"0",(VLOOKUP(D14,Sheet2!B:C,2,FALSE))) -> 0 | L14: =J14*K14 -> 0
A15: 4 | C15: =VLOOKUP(B15,Sheet2!W:X,2,FALSE) -> #N/A | F15: =IFERROR(VLOOKUP(E15,Sheet2!AD:AE,2,0),"") | G15: =VLOOKUP(B15,Sheet2!B:D,3,FALSE) -> #N/A | H15: SD | I15: A | K15: =IF(ISNA(VLOOKUP(D15,Sheet2!B:C,2,FALSE)),"0",(VLOOKUP(D15,Sheet2!B:C,2,FALSE))) -> 0 | L15: =J15*K15 -> 0
A16: 5 | C16: =VLOOKUP(B16,Sheet2!W:X,2,FALSE) -> #N/A | F16: =IFERROR(VLOOKUP(E16,Sheet2!AD:AE,2,0),"") | G16: =VLOOKUP(B16,Sheet2!B:D,3,FALSE) -> #N/A | H16: SD | I16: A | K16: =IF(ISNA(VLOOKUP(D16,Sheet2!B:C,2,FALSE)),"0",(VLOOKUP(D16,Sheet2!B:C,2,FALSE))) -> 0 | L16: =J16*K16 -> 0
A17: 6 | C17: =VLOOKUP(B17,Sheet2!W:X,2,FALSE) -> #N/A | F17: =IFERROR(VLOOKUP(E17,Sheet2!AD:AE,2,0),"") | G17: =VLOOKUP(B17,Sheet2!B:D,3,FALSE) -> #N/A | I17: A | K17: =IF(ISNA(VLOOKUP(D17,Sheet2!B:C,2,FALSE)),"0",(VLOOKUP(D17,Sheet2!B:C,2,FALSE))) -> 0 | L17: =J17*K17 -> 0
A18: 7 | C18: =VLOOKUP(B18,Sheet2!W:X,2,FALSE) -> #N/A | F18: =IFERROR(VLOOKUP(E18,Sheet2!AD:AE,2,0),"") | G18: =VLOOKUP(B18,Sheet2!B:D,3,FALSE) -> #N/A | I18: A | K18: =IF(ISNA(VLOOKUP(D18,Sheet2!B:C,2,FALSE)),"0",(VLOOKUP(D18,Sheet2!B:C,2,FALSE))) -> 0 | L18: =J18*K18 -> 0
A19: 8 | C19: =VLOOKUP(B19,Sheet2!W:X,2,FALSE) -> #N/A | F19: =IFERROR(VLOOKUP(E19,Sheet2!AD:AE,2,0),"") | G19: =VLOOKUP(B19,Sheet2!B:D,3,FALSE) -> #N/A | H19: SD | I19: A | K19: =IF(ISNA(VLOOKUP(D19,Sheet2!B:C,2,FALSE)),"0",(VLOOKUP(D19,Sheet2!B:C,2,FALSE))) -> 0 | L19: =J19*K19 -> 0
A20: 9 | C20: =VLOOKUP(B20,Sheet2!W:X,2,FALSE) -> #N/A | F20: =IFERROR(VLOOKUP(E20,Sheet2!AD:AE,2,0),"") | G20: =VLOOKUP(B20,Sheet2!B:D,3,FALSE) -> #N/A | H20: SD | I20: A | K20: =IF(ISNA(VLOOKUP(D20,Sheet2!B:C,2,FALSE)),"0",(VLOOKUP(D20,Sheet2!B:C,2,FALSE))) -> 0 | L20: =J20*K20 -> 0
A21: 10 | C21: =VLOOKUP(B21,Sheet2!W:X,2,FALSE) -> #N/A | F21: =IFERROR(VLOOKUP(E21,Sheet2!AD:AE,2,0),"") | G21: =VLOOKUP(B21,Sheet2!B:D,3,FALSE) -> #N/A | H21: SD | I21: A | K21: =IF(ISNA(VLOOKUP(D21,Sheet2!B:C,2,FALSE)),"0",(VLOOKUP(D21,Sheet2!B:C,2,FALSE))) -> 0 | L21: =J21*K21 -> 0
A22: 11 | C22: =VLOOKUP(B22,Sheet2!W:X,2,FALSE) -> #N/A | F22: =IFERROR(VLOOKUP(E22,Sheet2!AD:AE,2,0),"") | G22: =VLOOKUP(B22,Sheet2!B:D,3,FALSE) -> #N/A | I22: A | K22: =IF(ISNA(VLOOKUP(D22,Sheet2!B:C,2,FALSE)),"0",(VLOOKUP(D22,Sheet2!B:C,2,FALSE))) -> 0 | L22: =J22*K22 -> 0
A23: 12 | C23: =VLOOKUP(B23,Sheet2!W:X,2,FALSE) -> #N/A | F23: =IFERROR(VLOOKUP(E23,Sheet2!AD:AE,2,0),"") | G23: =VLOOKUP(B23,Sheet2!B:D,3,FALSE) -> #N/A | K23: =IF(ISNA(VLOOKUP(D23,Sheet2!B:C,2,FALSE)),"0",(VLOOKUP(D23,Sheet2!B:C,2,FALSE))) -> 0 | L23: =J23*K23 -> 0
A24: 13 | C24: =VLOOKUP(B24,Sheet2!W:X,2,FALSE) -> #N/A | F24: =IFERROR(VLOOKUP(E24,Sheet2!AD:AE,2,0),"") | G24: =VLOOKUP(B24,Sheet2!B:D,3,FALSE) -> #N/A | K24: =IF(ISNA(VLOOKUP(D24,Sheet2!B:C,2,FALSE)),"0",(VLOOKUP(D24,Sheet2!B:C,2,FALSE))) -> 0 | L24: =J24*K24 -> 0
A25: 14 | C25: =VLOOKUP(B25,Sheet2!W:X,2,FALSE) -> #N/A | F25: =IFERROR(VLOOKUP(E25,Sheet2!AD:AE,2,0),"") | G25: =VLOOKUP(B25,Sheet2!B:D,3,FALSE) -> #N/A | K25: =IF(ISNA(VLOOKUP(D25,Sheet2!B:C,2,FALSE)),"0",(VLOOKUP(D25,Sheet2!B:C,2,FALSE))) -> 0 | L25: =J25*K25 -> 0
A26: 15 | C26: =VLOOKUP(B26,Sheet2!W:X,2,FALSE) -> #N/A | F26: =IFERROR(VLOOKUP(E26,Sheet2!AD:AE,2,0),"") | G26: =VLOOKUP(B26,Sheet2!B:D,3,FALSE) -> #N/A | K26: =IF(ISNA(VLOOKUP(D26,Sheet2!B:C,2,FALSE)),"0",(VLOOKUP(D26,Sheet2!B:C,2,FALSE))) -> 0 | L26: =J26*K26 -> 0
A27: 16 | C27: =VLOOKUP(B27,Sheet2!W:X,2,FALSE) -> #N/A | F27: =IFERROR(VLOOKUP(E27,Sheet2!AD:AE,2,0),"") | G27: =VLOOKUP(B27,Sheet2!B:D,3,FALSE) -> #N/A | K27: =IF(ISNA(VLOOKUP(D27,Sheet2!B:C,2,FALSE)),"0",(VLOOKUP(D27,Sheet2!B:C,2,FALSE))) -> 0 | L27: =J27*K27 -> 0
A28: 17 | C28: =VLOOKUP(B28,Sheet2!W:X,2,FALSE) -> #N/A | F28: =IFERROR(VLOOKUP(E28,Sheet2!AD:AE,2,0),"") | G28: =VLOOKUP(B28,Sheet2!B:D,3,FALSE) -> #N/A | K28: =IF(ISNA(VLOOKUP(D28,Sheet2!B:C,2,FALSE)),"0",(VLOOKUP(D28,Sheet2!B:C,2,FALSE))) -> 0 | L28: =J28*K28 -> 0
A29: 18 | C29: =VLOOKUP(B29,Sheet2!W:X,2,FALSE) -> #N/A | F29: =IFERROR(VLOOKUP(E29,Sheet2!AD:AE,2,0),"") | G29: =VLOOKUP(B29,Sheet2!B:D,3,FALSE) -> #N/A | K29: =IF(ISNA(VLOOKUP(D29,Sheet2!B:C,2,FALSE)),"0",(VLOOKUP(D29,Sheet2!B:C,2,FALSE))) -> 0 | L29: =J29*K29 -> 0
A30: 19 | C30: =VLOOKUP(B30,Sheet2!W:X,2,FALSE) -> #N/A | F30: =IFERROR(VLOOKUP(E30,Sheet2!AD:AE,2,0),"") | G30: =VLOOKUP(B30,Sheet2!B:D,3,FALSE) -> #N/A | K30: =IF(ISNA(VLOOKUP(D30,Sheet2!B:C,2,FALSE)),"0",(VLOOKUP(D30,Sheet2!B:C,2,FALSE))) -> 0 | L30: =J30*K30 -> 0
A31: 20 | C31: =VLOOKUP(B31,Sheet2!W:X,2,FALSE) -> #N/A | F31: =IFERROR(VLOOKUP(E31,Sheet2!AD:AE,2,0),"") | G31: =VLOOKUP(B31,Sheet2!B:D,3,FALSE) -> #N/A | K31: =IF(ISNA(VLOOKUP(D31,Sheet2!B:C,2,FALSE)),"0",(VLOOKUP(D31,Sheet2!B:C,2,FALSE))) -> 0 | L31: =J31*K31 -> 0
F32: =IFERROR(VLOOKUP(E32,Sheet2!AD:AE,2,0),"")
A33: BRANCH (BOOKEDY BY NAME*) | D33: DFFD | H33: TOTAL | J33: =SUM(J12:J32) -> 1 | L33: =SUM(L12:L31) -> 47.37
A35: Special Remarks / Discounts
A39: Note : Pls recheck before sending order to HO about - Weight / Delivery Address / Extra Discount / Remarks. No Complaints will be entertain there after

Sheet Sheet2
A1: PRODUCTS | B1: PRODUCT CODE | C1: WEIGHT | E1: LM | I1: LP | M1: AH | Q1: UM | T1: LMR | U1: LH | W1: TYPE | X1: TYPE | Z1: TX | AA1: EM | AB1: CODE | AD1: VLOOK | AE1: 111 | AL1: LMRD | AP1: FM | AY1: AH+ | BD1: ornamate | BI1: EDGE_BAND
A2: PLAIN_MDF | B2: PLAIN_MDF | C2: PLAIN_MDF | E2: Design No. | F2: Design Name | I2: Design No. | J2: Design Name | M2: Design No. | N2: Design Name | O2: Width | Q2: Design No. | R2: Design Name | T2: Design No. | U2: Design Name | V2: Width | W2: PLAIN_MDF | X2: RM | Z2: MT | AA2: 403 | AB2: EGYPTA | AD2: Design No | AE2: Design Name | AG2: GRADE | AL2: Design No. | AM2: Design Name | AN2: Width | AP2: Design No. | AQ2: Design Name | AY2: Design No. | AZ2: Design Name | BA2: Width | BD2: Design No. | BE2: Design Name | BI2: Design No. | BJ2: Design Name | BM2: RM | BN2: MD-RM
A3: LAMINATED_MDF | B3: 01.90-I-8x4 | C3: 5.486 | E3: 1001 | F3: White Balancing | I3: 1001 | J3: White Balancing | M3: 8011 | N3: Silver Cross Line | Q3: 1101 | R3: Super White | T3: 1001 | U3: White Balancing | W3: LAMINATED_MDF | X3: LM | Z3: SD | AA3: 407 | AB3: NATURA | AD3: 1001 | AE3: White Balancing | AI3: A | AL3: 1001 | AM3: White Balancing | AN3: 4' | AP3: 3008 | AQ3: Straight Grained | AV3: LAMINATED_MDF | AW3: LM-MD | AY3: 8050 | AZ3: Super White GL | BD3: 1101 | BE3: Super White | BI3: 1102 | BJ3: Everest White | BM3: LM | BN3: LM-MD
A4: PLAIN_PARTICLE | B4: 02.10-I-8x4 | C4: 5.632 | E4: 1002 | F4: Frosty Balancing | I4: 1002 | J4: Frosty Balancing | M4: 8012 | N4: Brown Cross Line | Q4: 1102 | R4: Everest White | T4: 1002 | U4: Frosty Balancing | W4: PLAIN_PARTICLE | X4: RP | AA4: 410 | AB4: WEB | AD4: 1002 | AE4: Frosty Balancing | AI4: B | AL4: 1101 | AM4: Super White | AN4: 4' | AP4: 3345 | AQ4: Smoke Zebrano | AV4: LAMINATED_PARTICLE | AW4: LP-PB | AY4: 8051 | AZ4: Ivory White | BD4: 1102 | BE4: Everest White | BI4: 1103 | BJ4: Frosty White
A5: LAMINATED_PARTICLE | B5: 02.70-E-8x4 | C5: 6.591 | E5: 1101 | F5: Super White | I5: 1101 | J5: Super White | M5: 8013 | N5: 3D Mesh | Q5: 1103 | R5: Frosty White | T5: 1101 | U5: Super White | W5: LAMINATED_PARTICLE | X5: LP | Y5: TX | Z5: MT | AA5: 411 | AB5: CROWN TEAK | AD5: 1101 | AE5: Super White | AI5: CM | AL5: 1102 | AM5: Everest White | AN5: 4' | AP5: 3341 | AQ5: Chocolate Zebrano | AY5: 8052 | AZ5: Beige | BD5: 1103 | BE5: Frosty White | BI5: 1104 | BJ5: Silver Grey
A6: PLAIN_HMR_PARTICLE | B6: 02.70-E-8x7 | C6: 11.534 | E6: 1102 | F6: Everest White | I6: 1102 | J6: Everest White | M6: 8014 | N6: Checkered Red | Q6: 1104 | R6: Silver Grey | T6: 1102 | U6: Everest White | W6: LAMINATED_HMR_PARTICLE | X6: LP | Y6: TX | Z6: SD | AA6: 412 | AB6: CUBOID | AD6: 1102 | AE6: Everest White | AI6: C | AL6: 1103 | AM6: Frosty White | AN6: 4' | AP6: 3091 | AQ6: Teak Gold | AY6: 8053 | AZ6: Cappuccino | BD6: 1104 | BE6: Silver Grey | BI6: 1113 | BJ6: Gothic Grey
A7: LAMINATED_HMR_PARTICLE | B7: 03.30-I-8x4 | C7: 8.065 | E7: 1103 | F7: Frosty White | I7: 1103 | J7: Frosty White | M7: 8015 | N7: Checkered Beige | Q7: 1105 | R7: Slate Grey | T7: 1103 | U7: Frosty White | W7: PLAIN_HDHMR | X7: MR | Y7: TXD | Z7: MT | AA7: 413 | AB7: FLORINA | AD7: 1103 | AE7: Frosty White | AL7: 1104 | AM7: Silver Grey | AN7: 4' | AY7: 8054 | AZ7: Light Grey | BD7: 1105 | BE7: Slate Grey | BI7: 1105 | BJ7: Slate Grey
A8: PLAIN_HDHMR | B8: 03.30-E-8x4 | C8: 8.163 | E8: 1104 | F8: Silver Grey | I8: 1104 | J8: Silver Grey | M8: 8016 | N8: Acrylic Red | Q8: 1106 | R8: Black | T8: 1104 | U8: Silver Grey | W8: LAMINATED_HDHMR | X8: LMR | Y8: FM_TX | Z8: 4 | AA8: 414 | AB8: PLUME | AD8: 1104 | AE8: Silver Grey | AL8: 1105 | AM8: Slate Grey | AN8: 4' | AY8: 8055 | AZ8: Ash Grey | BD8: 1106 | BE8: Black | BI8: 1106 | BJ8: Black
A9: LAMINATED_HDHMR | B9: 04.00-I-8x4 | C9: 9.419 | E9: 1105 | F9: Slate Grey | I9: 1105 | J9: Slate Grey | M9: 8017 | N9: Feather | Q9: 1107 | R9: Cardinal Red | T9: 1105 | U9: Slate Grey | W9: UV | X9: UM | Y9: FM_TX | Z9: 5 | AA9: 415 | AB9: VEINS | AD9: 1105 | AE9: Slate Grey | AL9: 1106 | AM9: Black | AN9: 4' | AY9: 8056 | AZ9: Mocha Grey | BD9: 1113 | BE9: Gothic Grey | BI9: 1120 | BJ9: Irish Cream
A10: PLAIN_HDHMR_DOOR | B10: 04.60-I-8x4 | C10: 10.818 | E10: 1106 | F10: Black | I10: 1106 | J10: Black | M10: 8018 | N10: Graphite Grey | Q10: 1108 | R10: Marigold Yellow | T10: 1106 | U10: Black | W10: EMBOSSED | X10: EM | Y10: FM_TX | Z10: 6 | AA10: 418 | AB10: FLORA | AD10: 1106 | AE10: Black | AL10: 1107 | AM10: Cardinal Red | AN10: 4' | AY10: 8057 | AZ10: Dark Grey | BD10: 1120 | BE10: Irish Cream | BI10: 1131 | BJ10: Mud ash
A11: LAMINATED_HDHMR_DOOR | B11: 04.60-I-6X4 | C11: 8.113 | E11: 1107 | F11: Cardinal Red | I11: 1107 | J11: Cardinal Red | M11: 8019 | N11: Super Mozaic | Q11: 1109 | R11: Electric Blue | T11: 1107 | U11: Cardinal Red | W11: ACRYLIC | X11: AH | Y11: FM_TX | Z11: 7 | AA11: 425 | AB11: CHESS | AD11: 1107 | AE11: Cardinal Red | AL11: 1108 | AM11: Marigold Yellow | AN11: 4' | AY11: 8058 | AZ11: Black GL | BD11: 1131 | BE11: Mud Ash | BI11: 1134 | BJ11: Mocha Brown
A12: HDHMR_METALLIC_DOOR | B12: 05.50-I-10X4 | C12: 15.963 | E12: 1108 | F12: Marigold Yellow | I12: 1108 | J12: Marigold Yellow | M12: 8022 | N12: Brushed Grey | Q12: 1111 | R12: Ivory | T12: 1108 | U12: Marigold Yellow | W12: PLAIN_HDHMR_DOOR | X12: MRD | AA12: 426 | AB12: PETAL | AD12: 1108 | AE12: Marigold Yellow | AL12: 1109 | AM12: Electric Blue | AN12: 4' | AY12: 8059 | AZ12: Matte Blue | BD12: 1134 | BE12: Mocha Brown | BI12: 1136 | BJ12: Ocean Green
A13: PLAIN_BOILO | B13: 05.50-I-8x6 | C13: 19.16 | E13: 1109 | F13: Electric Blue | I13: 1109 | J13: Electric Blue | M13: 8023 | N13: Silver Grey | Q13: 1113 | R13: Gothic Grey | T13: 1109 | U13: Electric Blue | W13: LAMINATED_HDHMR_DOOR | X13: LMRD | AA13: 427 | AB13: AMOEBA | AD13: 1109 | AE13: Electric Blue | AL13: 1111 | AM13: Ivory | AN13: 4' | AY13: 8060 | AZ13: Scarlet Red | BD13: 1136 | BE13: Ocean Green | BI13: 1137 | BJ13: Persian Blue
A14: LAMINATED_BOILO | B14: 05.50-I-8x4 | C14: 12.77 | E14: 1111 | F14: Ivory | I14: 1111 | J14: Ivory | Q14: 1115 | R14: Spanish Green | T14: 1111 | U14: Ivory | W14: HDHMR_METALLIC_DOOR | X14: FM | AA14: 429 | AB14: BUTTERFLY | AD14: 1111 | AE14: Ivory | AL14: 1112 | AM14: Alu Wave | AN14: 4' | AY14: 8061 | AZ14: French Violet | BD14: 1137 | BE14: Persian Blue | BI14: 1141 | BJ14: Night Grey
A15: EMBOSSED | B15: 05.50-E-8X4. | C15: 12.77 | E15: 1113 | F15: Gothic Grey | I15: 1113 | J15: Gothic Grey | Q15: 1116 | R15: Orange | T15: 1113 | U15: Gothic Grey | W15: LAMINATED_BOILO | X15: LH | Y15: MT | AA15: 430 | AB15: FABRIC | AD15: 1113 | AE15: Gothic Grey | AL15: 1113 | AM15: Gothic Grey | AN15: 4' | AY15: 8062 | AZ15: Sage | BD15: 1141 | BE15: Night Grey | BI15: 1142 | BJ15: Pebble Beech
A16: UV | B16: 07.00-I-8x4 | C16: 15.837 | E16: 1115 | F16: Spanish Green | I16: 1116 | J16: Orange | Q16: 1118 | R16: Burgandy Red | T16: 1115 | U16: Spanish Green | W16: Ornamate | X16: OM | Y16: SD | AA16: 434 | AB16: LEAF | AD16: 1115 | AE16: Spanish Green | AL16: 1115 | AM16: Spanish Green | AN16: 4' | AY16: 8063 | AZ16: White Metallic | BD16: 1142 | BE16: Pebble Beech | BI16: 1143 | BJ16: Coral Pink
A17: ACRYLIC | B17: 07.30-E-8x4 | C17: 16.733 | E17: 1116 | F17: Orange | I17: 1119 | J17: Parrot Green | Q17: 1119 | R17: Parrot Green | T17: 1116 | U17: Orange | W17: PLAIN_BOILO | X17: RH | AA17: 435 | AB17: MATS | AD17: 1116 | AE17: Orange | AL17: 1116 | AM17: Orange | AN17: 4' | AY17: 8064 | AZ17: Silver Metallic | BD17: 1143 | BE17: Coral Pink | BI17: 1151 | BJ17: Mouse Grey
A18: ACRYLIC_PLUS | B18: 07.30-I-8X6 | C18: 24.61 | E18: 1118 | F18: Burgandy Red | I18: 1120 | J18: Irish Cream | Q18: 1120 | R18: Irish Cream | T18: 1118 | U18: Burgandy Red | W18: ACRYLIC_PLUS | X18: AHPL | AA18: 436 | AB18: HONEYCOMB | AD18: 1118 | AE18: Burgandy Red | AL18: 1119 | AM18: Parrot Green | AN18: 4' | AY18: 8065 | AZ18: Black Metallic | BD18: 1151 | BE18: Mouse Grey | BI18: 1152 | BJ18: Warm Blue
A19: Ornamate | B19: 07.30-I-8x4 | C19: 16.407 | E19: 1119 | F19: Parrot Green | I19: 1126 | J19: Hutch Pink | Q19: 1123 | R19: Dark Violet | T19: 1119 | U19: Parrot Green | W19: Ornamatte Edge Band Tape | X19: EDGE | AA19: 438 | AB19: SANDMARKS | AD19: 1119 | AE19: Parrot Green | AL19: 1125 | AM19: Celestial Blue | AN19: 4' | AY19: 8066 | AZ19: Blue Metallic | BD19: 1152 | BE19: Warm Blue | BI19: 1153 | BJ19: Midnight Blue
A20: Ornamatte Edge Band Tape | B20: 09.75-I-10X4 | C20: 27.391 | E20: 1120 | F20: Irish Cream | I20: 1129 | J20: Caribe | Q20: 1126 | R20: Hutch Pink | T20: 1120 | U20: Irish Cream | AA20: 439 | AB20: KNURL | AD20: 1120 | AE20: Irish Cream | AL20: 1126 | AM20: Hutch Pink | AN20: 4' | AY20: 8067 | AZ20: Super White MT | BD20: 1153 | BE20: Midnight Blue | BI20: 1154 | BJ20: Wasabi Green
B21: 09.75-I-8x4 | C21: 21.913 | E21: 1123 | F21: Dark Violet | I21: 1133 | J21: Pastel Orange | Q21: 1129 | R21: Caribe | T21: 1123 | U21: Dark Violet | AA21: 440 | AB21: SPIRALS | AD21: 1123 | AE21: Dark Violet | AL21: 1129 | AM21: Caribe | AN21: 4' | AY21: 8068 | AZ21: Off White | BD21: 1154 | BE21: Wasabi Green | BI21: 1155 | BJ21: Warm Brown
B22: 11.00-I-10X4 | C22: 30.903 | E22: 1126 | F22: Hutch Pink | I22: 1134 | J22: Mocha Brown | Q22: 1130 | R22: Peanut | T22: 1126 | U22: Hutch Pink | AA22: 441 | AB22: SWIRL | AD22: 1126 | AE22: Hutch Pink | AL22: 1130 | AM22: Peanut. | AN22: 4' | AY22: 8069 | AZ22: Stone Grey | BD22: 1155 | BE22: Warm Brown | BI22: 1156 | BJ22: Plum
B23: 11.00-E-8x4. | C23: 25.05 | E23: 1129 | F23: Caribe | I23: 1135 | J23: Olive | Q23: 1131 | R23: Mud Ash | T23: 1129 | U23: Caribe | AA23: 442 | AB23: TREAD MARK | AD23: 1129 | AE23: Caribe | AL23: 1131 | AM23: Mud Ash. | AN23: 4' | AY23: 8070 | AZ23: Magma Grey | BD23: 1156 | BE23: Plum | BI23: 3461 | BJ23: Novel Walnut
B24: 11.00-I-8x4 | C24: 25.213 | E24: 1130 | F24: Peanut | I24: 1138 | J24: Hong Kong Blue | Q24: 1133 | R24: Pastel Orange | T24: 1130 | U24: Peanut | AA24: 443 | AB24: FLORAL | AD24: 1130 | AE24: Peanut | AL24: 1133 | AM24: Pastel Orange | AN24: 4' | AY24: 8071 | AZ24: Black MT | BD24: 1157 | BE24: Brown Cappuccino | BI24: 3462 | BJ24: Natural Walnut
B25: 11.00-I-8X6. | C25: 37.82 | E25: 1131 | F25: Mud Ash | I25: 1140 | J25: Irish Blue | Q25: 1134 | R25: Mocha Brown | T25: 1131 | U25: Mud Ash | AA25: 446 | AB25: VINE | AD25: 1131 | AE25: Mud Ash | AL25: 1134 | AM25: Mocha Brown | AN25: 4' | AY25: 8072 | AZ25: Stone Blue | BD25: 3461 | BE25: Novel Walnut | BI25: 3469 | BJ25: Calm Nubuck
B26: 14.50-I-8x4 | C26: 32.589 | E26: 1134 | F26: Mocha Brown | I26: 1141 | J26: Night Grey | Q26: 1135 | R26: Olive | T26: 1134 | U26: Mocha Brown | AA26: 447 | AB26: BLADE | AD26: 1133 | AE26: Pastel Orange | AL26: 1135 | AM26: Olive | AN26: 4' | AY26: 8073 | AZ26: Soft Beige | BD26: 3462 | BE26: Natural Walnut | BI26: 3470 | BJ26: Chic Nubuck
B27: 16.00-I-8x4 | C27: 35.722 | E27: 1135 | F27: Olive | I27: 1142 | J27: Pebble Beach | Q27: 1136 | R27: Ocean Green | T27: 1135 | U27: Olive | AA27: 449 | AB27: JASMINE | AD27: 1134 | AE27: Mocha Brown | AL27: 1136 | AM27: Ocean Green | AN27: 4' | AY27: 8074 | AZ27: Dove Grey | BD27: 3467 | BE27: Milk Statuary Marble | BI27: 3472 | BJ27: Auburn Oak
B28: 16.50-I-8x4 | C28: 37.329 | E28: 1136 | F28: Ocean Green | I28: 1143 | J28: Coral Pink | Q28: 1137 | R28: Persian Blue | T28: 1136 | U28: Ocean Green | AA28: 450 | AB28: STENCIL | AD28: 1135 | AE28: Olive | AL28: 1137 | AM28: Persian Blue | AN28: 4' | AY28: 8075 | AZ28: Amazon Blue | BD28: 3469 | BE28: Calm Nubuck | BI28: 3473 | BJ28: Carrara Marble
B29: 16.50-I-8X6 | C29: 55.994 | E29: 1137 | F29: Persian Blue | I29: 1144 | J29: Chocolate | Q29: 1138 | R29: Hong Kong Blue | T29: 1137 | U29: Persian Blue | AA29: 451 | AB29: CURLED | AD29: 1136 | AE29: Ocean Green | AL29: 1138 | AM29: Hong Kong Blue | AN29: 4' | AY29: 8076 | AZ29: Rose Beige | BD29: 3470 | BE29: Chic Nubuck | BI29: 3474 | BJ29: Grey Stone
B30: 17.00-I-10X4 | C30: 48.075 | E30: 1138 | F30: Hong Kong Blue | I30: 3001 | J30: Natural Teak | Q30: 1139 | R30: Pink Irish Cream | T30: 1138 | U30: Hong Kong Blue | AA30: 452 | AB30: OLIVE | AD30: 1137 | AE30: Persian Blue | AL30: 3001 | AM30: Natural Teak | AN30: 4' | AY30: 8077 | AZ30: Graphite | BD30: 3471 | BE30: Virgin Oak | BI30: 3475 | BJ30: Glacier Stone
B31: 17.00-I-8x4 | C31: 38.46 | E31: 1139 | F31: Pink Irish Cream | I31: 3002 | J31: Flowery Wenge | Q31: 1140 | R31: Irish Blue | T31: 1139 | U31: Pink Irish Cream | AA31: 453 | AB31: GEOMETRIC | AD31: 1138 | AE31: Hong Kong Blue | AL31: 3002 | AM31: Flowery Wenge | AN31: 4' | AY31: 8078 | AZ31: Beige Metallic | BD31: 3472 | BE31: Auburn Oak | BI31: 1157 | BJ31: Brown Cappuccino
B32: 17.00-E-8x4 | C32: 38.46 | E32: 1141 | F32: Night Grey | I32: 3003 | J32: Highland Pine | Q32: 1141 | R32: Night Grey | T32: 1141 | U32: Night Grey | AA32: 454 | AB32: HEXA | AD32: 1139 | AE32: Pink Irish Cream | AL32: 3003 | AM32: Highland Pine | AN32: 4' | AY32: 8079 | AZ32: Steel Grey | BD32: 3473 | BE32: Carrara Marble | BI32: 3467 | BJ32: Milk Statuary Marble
B33: 17.00-I-8X6. | C33: 57.69 | E33: 1142 | F33: Pebble Beach | I33: 3007 | J33: Lorraine Walnut | Q33: 1142 | R33: Pebble Beach | T33: 1142 | U33: Pebble Beach | AA33: 455 | AB33: TURNIP | AD33: 1140 | AE33: Irish Blue | AL33: 3007 | AM33: Lorraine Walnut | AN33: 4' | BD33: 3474 | BE33: Grey Stone | BI33: 3471 | BJ33: Virgin Oak
B34: 18.00-E-8x4. | C34: 40.723 | E34: 1143 | F34: Coral Pink | I34: 3008 | J34: Straight Grained Wenge | Q34: 1143 | R34: Coral Pink | T34: 1143 | U34: Coral Pink | AD34: 1141 | AE34: Night Grey | AL34: 3008 | AM34: Straight Grained Wenge | AN34: 4' | BD34: 3475 | BE34: Glacier Stone | BI34: 1101 | BJ34: White
B35: 18.00-I-8x4 | C35: 40.723 | E35: 1144 | F35: Chocolate | I35: 3009 | J35: Classic Planked Walnut | Q35: 1144 | R35: Chocolate | T35: 1144 | U35: Chocolate | AD35: 1142 | AE35: Pebble Beach | AL35: 3009 | AM35: Classic Planked Walnut | AN35: 4'
B36: 18.00-I-8X6. | C36: 61.084 | E36: 1151 | F36: Mouse Grey | I36: 3013 | J36: New Country Light | Q36: 1151 | R36: Mouse Grey | T36: 1151 | U36: Mouse Grey | AD36: 1143 | AE36: Coral Pink | AL36: 3013 | AM36: New Country Light | AN36: 4'
B37: 25.00-E-8x4. | C37: 55.071 | E37: 1152 | F37: Warm Blue | I37: 3015 | J37: Sapelli | Q37: 1152 | R37: Warm Blue | T37: 1152 | U37: Warm Blue | AD37: 1144 | AE37: Chocolate | AL37: 3015 | AM37: Sapelli | AN37: 4'
B38: 25.00-I-8x4 | C38: 54.327 | E38: 1153 | F38: Midnight Blue | I38: 3016 | J38: Inntal Beech | Q38: 1153 | R38: Midnight Blue | T38: 1153 | U38: Midnight Blue | AD38: 1151 | AE38: Mouse Grey | AL38: 3017 | AM38: Noce Di Vinci | AN38: 4'
B39: 25.00-I-8X6. | C39: 81.49 | E39: 1154 | F39: Wasabi Green | I39: 3017 | J39: Noce Di Vinci | Q39: 1154 | R39: Wasabi Green | T39: 1154 | U39: Wasabi Green | AD39: 1152 | AE39: Warm Blue | AL39: 3018 | AM39: Mangfall Beech | AN39: 4'
B40: LAMINATED_MDF | C40: LAMINATED_MDF | D40: TX_MDF | E40: 1155 | F40: Warm Brown | I40: 3018 | J40: Mangfall Beech | Q40: 1155 | R40: Warm Brown | T40: 1155 | U40: Warm Brown | AD40: 1153 | AE40: Midnight Blue | AL40: 3019 | AM40: Ice Beech | AN40: 4'
...
